Request: POST /flow/banner/
JSON data: {
    "amount": 100,
    "payment_method": "wechat",
    "pay_type": 4,
    "desc": "1"
}
Response: 405
Request: GET /flow/banner/
Form data: <QueryDict: {}>
Internal Server Error: /flow/banner/
Traceback (most recent call last):
  File "/opt/anaconda3/envs/casher/lib/python3.11/site-packages/django/db/backends/base/base.py", line 289, in ensure_connection
    self.connect()
  File "/opt/anaconda3/envs/casher/lib/python3.11/site-packages/django/utils/asyncio.py", line 26, in inner
    return func(*args, **kwargs)
           ^^^^^^^^^^^^^^^^^^^^^
  File "/opt/anaconda3/envs/casher/lib/python3.11/site-packages/django/db/backends/base/base.py", line 270, in connect
    self.connection = self.get_new_connection(conn_params)
                      ^^^^^^^^^^^^^^^^^^^^^^^^^^^^^^^^^^^^
  File "/opt/anaconda3/envs/casher/lib/python3.11/site-packages/django/utils/asyncio.py", line 26, in inner
    return func(*args, **kwargs)
           ^^^^^^^^^^^^^^^^^^^^^
  File "/opt/anaconda3/envs/casher/lib/python3.11/site-packages/django/db/backends/mysql/base.py", line 247, in get_new_connection
    connection = Database.connect(**conn_params)
                 ^^^^^^^^^^^^^^^^^^^^^^^^^^^^^^^
  File "/opt/anaconda3/envs/casher/lib/python3.11/site-packages/MySQLdb/__init__.py", line 130, in Connect
    return Connection(*args, **kwargs)
           ^^^^^^^^^^^^^^^^^^^^^^^^^^^
  File "/opt/anaconda3/envs/casher/lib/python3.11/site-packages/MySQLdb/connections.py", line 185, in __init__
    super().__init__(*args, **kwargs2)
MySQLdb._exceptions.OperationalError: (2003, "Can't connect to MySQL server on '192.168.10.100' (61)")

The above exception was the direct cause of the following exception:

Traceback (most recent call last):
  File "/opt/anaconda3/envs/casher/lib/python3.11/site-packages/asgiref/sync.py", line 518, in thread_handler
    raise exc_info[1]
  File "/opt/anaconda3/envs/casher/lib/python3.11/site-packages/django/core/handlers/exception.py", line 42, in inner
    response = await get_response(request)
               ^^^^^^^^^^^^^^^^^^^^^^^^^^^
  File "/opt/anaconda3/envs/casher/lib/python3.11/site-packages/asgiref/sync.py", line 518, in thread_handler
    raise exc_info[1]
  File "/opt/anaconda3/envs/casher/lib/python3.11/site-packages/django/core/handlers/base.py", line 253, in _get_response_async
    response = await wrapped_callback(
               ^^^^^^^^^^^^^^^^^^^^^^^
  File "/opt/anaconda3/envs/casher/lib/python3.11/site-packages/asgiref/sync.py", line 468, in __call__
    ret = await asyncio.shield(exec_coro)
          ^^^^^^^^^^^^^^^^^^^^^^^^^^^^^^^
  File "/opt/anaconda3/envs/casher/lib/python3.11/site-packages/asgiref/current_thread_executor.py", line 40, in run
    result = self.fn(*self.args, **self.kwargs)
             ^^^^^^^^^^^^^^^^^^^^^^^^^^^^^^^^^^
  File "/opt/anaconda3/envs/casher/lib/python3.11/site-packages/asgiref/sync.py", line 522, in thread_handler
    return func(*args, **kwargs)
           ^^^^^^^^^^^^^^^^^^^^^
  File "/opt/anaconda3/envs/casher/lib/python3.11/site-packages/django/views/decorators/csrf.py", line 56, in wrapper_view
    return view_func(*args, **kwargs)
           ^^^^^^^^^^^^^^^^^^^^^^^^^^
  File "/opt/anaconda3/envs/casher/lib/python3.11/site-packages/django/views/generic/base.py", line 104, in view
    return self.dispatch(request, *args, **kwargs)
           ^^^^^^^^^^^^^^^^^^^^^^^^^^^^^^^^^^^^^^^
  File "/opt/anaconda3/envs/casher/lib/python3.11/site-packages/rest_framework/views.py", line 509, in dispatch
    response = self.handle_exception(exc)
               ^^^^^^^^^^^^^^^^^^^^^^^^^^
  File "/opt/anaconda3/envs/casher/lib/python3.11/site-packages/rest_framework/views.py", line 469, in handle_exception
    self.raise_uncaught_exception(exc)
  File "/opt/anaconda3/envs/casher/lib/python3.11/site-packages/rest_framework/views.py", line 480, in raise_uncaught_exception
    raise exc
  File "/opt/anaconda3/envs/casher/lib/python3.11/site-packages/rest_framework/views.py", line 506, in dispatch
    response = handler(request, *args, **kwargs)
               ^^^^^^^^^^^^^^^^^^^^^^^^^^^^^^^^^
  File "/Users/amaozhao/workspace/casher/flow/views.py", line 535, in get
    banner = WorkFlowBanner.objects.first()
             ^^^^^^^^^^^^^^^^^^^^^^^^^^^^^^
  File "/opt/anaconda3/envs/casher/lib/python3.11/site-packages/django/db/models/manager.py", line 87, in manager_method
    return getattr(self.get_queryset(), name)(*args, **kwargs)
           ^^^^^^^^^^^^^^^^^^^^^^^^^^^^^^^^^^^^^^^^^^^^^^^^^^^
  File "/opt/anaconda3/envs/casher/lib/python3.11/site-packages/django/db/models/query.py", line 1057, in first
    for obj in queryset[:1]:
  File "/opt/anaconda3/envs/casher/lib/python3.11/site-packages/django/db/models/query.py", line 398, in __iter__
    self._fetch_all()
  File "/opt/anaconda3/envs/casher/lib/python3.11/site-packages/django/db/models/query.py", line 1881, in _fetch_all
    self._result_cache = list(self._iterable_class(self))
                         ^^^^^^^^^^^^^^^^^^^^^^^^^^^^^^^^
  File "/opt/anaconda3/envs/casher/lib/python3.11/site-packages/django/db/models/query.py", line 91, in __iter__
    results = compiler.execute_sql(
              ^^^^^^^^^^^^^^^^^^^^^
  File "/opt/anaconda3/envs/casher/lib/python3.11/site-packages/django/db/models/sql/compiler.py", line 1560, in execute_sql
    cursor = self.connection.cursor()
             ^^^^^^^^^^^^^^^^^^^^^^^^
  File "/opt/anaconda3/envs/casher/lib/python3.11/site-packages/django/utils/asyncio.py", line 26, in inner
    return func(*args, **kwargs)
           ^^^^^^^^^^^^^^^^^^^^^
  File "/opt/anaconda3/envs/casher/lib/python3.11/site-packages/django/db/backends/base/base.py", line 330, in cursor
    return self._cursor()
           ^^^^^^^^^^^^^^
  File "/opt/anaconda3/envs/casher/lib/python3.11/site-packages/django/db/backends/base/base.py", line 306, in _cursor
    self.ensure_connection()
  File "/opt/anaconda3/envs/casher/lib/python3.11/site-packages/django/utils/asyncio.py", line 26, in inner
    return func(*args, **kwargs)
           ^^^^^^^^^^^^^^^^^^^^^
  File "/opt/anaconda3/envs/casher/lib/python3.11/site-packages/django/db/backends/base/base.py", line 288, in ensure_connection
    with self.wrap_database_errors:
  File "/opt/anaconda3/envs/casher/lib/python3.11/site-packages/django/db/utils.py", line 91, in __exit__
    raise dj_exc_value.with_traceback(traceback) from exc_value
  File "/opt/anaconda3/envs/casher/lib/python3.11/site-packages/django/db/backends/base/base.py", line 289, in ensure_connection
    self.connect()
  File "/opt/anaconda3/envs/casher/lib/python3.11/site-packages/django/utils/asyncio.py", line 26, in inner
    return func(*args, **kwargs)
           ^^^^^^^^^^^^^^^^^^^^^
  File "/opt/anaconda3/envs/casher/lib/python3.11/site-packages/django/db/backends/base/base.py", line 270, in connect
    self.connection = self.get_new_connection(conn_params)
                      ^^^^^^^^^^^^^^^^^^^^^^^^^^^^^^^^^^^^
  File "/opt/anaconda3/envs/casher/lib/python3.11/site-packages/django/utils/asyncio.py", line 26, in inner
    return func(*args, **kwargs)
           ^^^^^^^^^^^^^^^^^^^^^
  File "/opt/anaconda3/envs/casher/lib/python3.11/site-packages/django/db/backends/mysql/base.py", line 247, in get_new_connection
    connection = Database.connect(**conn_params)
                 ^^^^^^^^^^^^^^^^^^^^^^^^^^^^^^^
  File "/opt/anaconda3/envs/casher/lib/python3.11/site-packages/MySQLdb/__init__.py", line 130, in Connect
    return Connection(*args, **kwargs)
           ^^^^^^^^^^^^^^^^^^^^^^^^^^^
  File "/opt/anaconda3/envs/casher/lib/python3.11/site-packages/MySQLdb/connections.py", line 185, in __init__
    super().__init__(*args, **kwargs2)
django.db.utils.OperationalError: (2003, "Can't connect to MySQL server on '192.168.10.100' (61)")
Response: 500
Request: GET /flow/banner/
Form data: <QueryDict: {}>
Internal Server Error: /flow/banner/
Traceback (most recent call last):
  File "/opt/anaconda3/envs/casher/lib/python3.11/site-packages/django/db/backends/base/base.py", line 289, in ensure_connection
    self.connect()
  File "/opt/anaconda3/envs/casher/lib/python3.11/site-packages/django/utils/asyncio.py", line 26, in inner
    return func(*args, **kwargs)
           ^^^^^^^^^^^^^^^^^^^^^
  File "/opt/anaconda3/envs/casher/lib/python3.11/site-packages/django/db/backends/base/base.py", line 270, in connect
    self.connection = self.get_new_connection(conn_params)
                      ^^^^^^^^^^^^^^^^^^^^^^^^^^^^^^^^^^^^
  File "/opt/anaconda3/envs/casher/lib/python3.11/site-packages/django/utils/asyncio.py", line 26, in inner
    return func(*args, **kwargs)
           ^^^^^^^^^^^^^^^^^^^^^
  File "/opt/anaconda3/envs/casher/lib/python3.11/site-packages/django/db/backends/mysql/base.py", line 247, in get_new_connection
    connection = Database.connect(**conn_params)
                 ^^^^^^^^^^^^^^^^^^^^^^^^^^^^^^^
  File "/opt/anaconda3/envs/casher/lib/python3.11/site-packages/MySQLdb/__init__.py", line 130, in Connect
    return Connection(*args, **kwargs)
           ^^^^^^^^^^^^^^^^^^^^^^^^^^^
  File "/opt/anaconda3/envs/casher/lib/python3.11/site-packages/MySQLdb/connections.py", line 185, in __init__
    super().__init__(*args, **kwargs2)
MySQLdb._exceptions.OperationalError: (2003, "Can't connect to MySQL server on '192.168.10.100' (61)")

The above exception was the direct cause of the following exception:

Traceback (most recent call last):
  File "/opt/anaconda3/envs/casher/lib/python3.11/site-packages/asgiref/sync.py", line 518, in thread_handler
    raise exc_info[1]
  File "/opt/anaconda3/envs/casher/lib/python3.11/site-packages/django/core/handlers/exception.py", line 42, in inner
    response = await get_response(request)
               ^^^^^^^^^^^^^^^^^^^^^^^^^^^
  File "/opt/anaconda3/envs/casher/lib/python3.11/site-packages/asgiref/sync.py", line 518, in thread_handler
    raise exc_info[1]
  File "/opt/anaconda3/envs/casher/lib/python3.11/site-packages/django/core/handlers/base.py", line 253, in _get_response_async
    response = await wrapped_callback(
               ^^^^^^^^^^^^^^^^^^^^^^^
  File "/opt/anaconda3/envs/casher/lib/python3.11/site-packages/asgiref/sync.py", line 468, in __call__
    ret = await asyncio.shield(exec_coro)
          ^^^^^^^^^^^^^^^^^^^^^^^^^^^^^^^
  File "/opt/anaconda3/envs/casher/lib/python3.11/site-packages/asgiref/current_thread_executor.py", line 40, in run
    result = self.fn(*self.args, **self.kwargs)
             ^^^^^^^^^^^^^^^^^^^^^^^^^^^^^^^^^^
  File "/opt/anaconda3/envs/casher/lib/python3.11/site-packages/asgiref/sync.py", line 522, in thread_handler
    return func(*args, **kwargs)
           ^^^^^^^^^^^^^^^^^^^^^
  File "/opt/anaconda3/envs/casher/lib/python3.11/site-packages/django/views/decorators/csrf.py", line 56, in wrapper_view
    return view_func(*args, **kwargs)
           ^^^^^^^^^^^^^^^^^^^^^^^^^^
  File "/opt/anaconda3/envs/casher/lib/python3.11/site-packages/django/views/generic/base.py", line 104, in view
    return self.dispatch(request, *args, **kwargs)
           ^^^^^^^^^^^^^^^^^^^^^^^^^^^^^^^^^^^^^^^
  File "/opt/anaconda3/envs/casher/lib/python3.11/site-packages/rest_framework/views.py", line 509, in dispatch
    response = self.handle_exception(exc)
               ^^^^^^^^^^^^^^^^^^^^^^^^^^
  File "/opt/anaconda3/envs/casher/lib/python3.11/site-packages/rest_framework/views.py", line 469, in handle_exception
    self.raise_uncaught_exception(exc)
  File "/opt/anaconda3/envs/casher/lib/python3.11/site-packages/rest_framework/views.py", line 480, in raise_uncaught_exception
    raise exc
  File "/opt/anaconda3/envs/casher/lib/python3.11/site-packages/rest_framework/views.py", line 506, in dispatch
    response = handler(request, *args, **kwargs)
               ^^^^^^^^^^^^^^^^^^^^^^^^^^^^^^^^^
  File "/Users/amaozhao/workspace/casher/flow/views.py", line 535, in get
    banner = WorkFlowBanner.objects.first()
             ^^^^^^^^^^^^^^^^^^^^^^^^^^^^^^
  File "/opt/anaconda3/envs/casher/lib/python3.11/site-packages/django/db/models/manager.py", line 87, in manager_method
    return getattr(self.get_queryset(), name)(*args, **kwargs)
           ^^^^^^^^^^^^^^^^^^^^^^^^^^^^^^^^^^^^^^^^^^^^^^^^^^^
  File "/opt/anaconda3/envs/casher/lib/python3.11/site-packages/django/db/models/query.py", line 1057, in first
    for obj in queryset[:1]:
  File "/opt/anaconda3/envs/casher/lib/python3.11/site-packages/django/db/models/query.py", line 398, in __iter__
    self._fetch_all()
  File "/opt/anaconda3/envs/casher/lib/python3.11/site-packages/django/db/models/query.py", line 1881, in _fetch_all
    self._result_cache = list(self._iterable_class(self))
                         ^^^^^^^^^^^^^^^^^^^^^^^^^^^^^^^^
  File "/opt/anaconda3/envs/casher/lib/python3.11/site-packages/django/db/models/query.py", line 91, in __iter__
    results = compiler.execute_sql(
              ^^^^^^^^^^^^^^^^^^^^^
  File "/opt/anaconda3/envs/casher/lib/python3.11/site-packages/django/db/models/sql/compiler.py", line 1560, in execute_sql
    cursor = self.connection.cursor()
             ^^^^^^^^^^^^^^^^^^^^^^^^
  File "/opt/anaconda3/envs/casher/lib/python3.11/site-packages/django/utils/asyncio.py", line 26, in inner
    return func(*args, **kwargs)
           ^^^^^^^^^^^^^^^^^^^^^
  File "/opt/anaconda3/envs/casher/lib/python3.11/site-packages/django/db/backends/base/base.py", line 330, in cursor
    return self._cursor()
           ^^^^^^^^^^^^^^
  File "/opt/anaconda3/envs/casher/lib/python3.11/site-packages/django/db/backends/base/base.py", line 306, in _cursor
    self.ensure_connection()
  File "/opt/anaconda3/envs/casher/lib/python3.11/site-packages/django/utils/asyncio.py", line 26, in inner
    return func(*args, **kwargs)
           ^^^^^^^^^^^^^^^^^^^^^
  File "/opt/anaconda3/envs/casher/lib/python3.11/site-packages/django/db/backends/base/base.py", line 288, in ensure_connection
    with self.wrap_database_errors:
  File "/opt/anaconda3/envs/casher/lib/python3.11/site-packages/django/db/utils.py", line 91, in __exit__
    raise dj_exc_value.with_traceback(traceback) from exc_value
  File "/opt/anaconda3/envs/casher/lib/python3.11/site-packages/django/db/backends/base/base.py", line 289, in ensure_connection
    self.connect()
  File "/opt/anaconda3/envs/casher/lib/python3.11/site-packages/django/utils/asyncio.py", line 26, in inner
    return func(*args, **kwargs)
           ^^^^^^^^^^^^^^^^^^^^^
  File "/opt/anaconda3/envs/casher/lib/python3.11/site-packages/django/db/backends/base/base.py", line 270, in connect
    self.connection = self.get_new_connection(conn_params)
                      ^^^^^^^^^^^^^^^^^^^^^^^^^^^^^^^^^^^^
  File "/opt/anaconda3/envs/casher/lib/python3.11/site-packages/django/utils/asyncio.py", line 26, in inner
    return func(*args, **kwargs)
           ^^^^^^^^^^^^^^^^^^^^^
  File "/opt/anaconda3/envs/casher/lib/python3.11/site-packages/django/db/backends/mysql/base.py", line 247, in get_new_connection
    connection = Database.connect(**conn_params)
                 ^^^^^^^^^^^^^^^^^^^^^^^^^^^^^^^
  File "/opt/anaconda3/envs/casher/lib/python3.11/site-packages/MySQLdb/__init__.py", line 130, in Connect
    return Connection(*args, **kwargs)
           ^^^^^^^^^^^^^^^^^^^^^^^^^^^
  File "/opt/anaconda3/envs/casher/lib/python3.11/site-packages/MySQLdb/connections.py", line 185, in __init__
    super().__init__(*args, **kwargs2)
django.db.utils.OperationalError: (2003, "Can't connect to MySQL server on '192.168.10.100' (61)")
Response: 500
Request: GET /favicon.ico
Form data: <QueryDict: {}>
Response: 404
Request: GET /flow/banner/
Form data: <QueryDict: {}>
Internal Server Error: /flow/banner/
Traceback (most recent call last):
  File "/opt/anaconda3/envs/casher/lib/python3.11/site-packages/django/db/backends/base/base.py", line 289, in ensure_connection
    self.connect()
  File "/opt/anaconda3/envs/casher/lib/python3.11/site-packages/django/utils/asyncio.py", line 26, in inner
    return func(*args, **kwargs)
           ^^^^^^^^^^^^^^^^^^^^^
  File "/opt/anaconda3/envs/casher/lib/python3.11/site-packages/django/db/backends/base/base.py", line 270, in connect
    self.connection = self.get_new_connection(conn_params)
                      ^^^^^^^^^^^^^^^^^^^^^^^^^^^^^^^^^^^^
  File "/opt/anaconda3/envs/casher/lib/python3.11/site-packages/django/utils/asyncio.py", line 26, in inner
    return func(*args, **kwargs)
           ^^^^^^^^^^^^^^^^^^^^^
  File "/opt/anaconda3/envs/casher/lib/python3.11/site-packages/django/db/backends/mysql/base.py", line 247, in get_new_connection
    connection = Database.connect(**conn_params)
                 ^^^^^^^^^^^^^^^^^^^^^^^^^^^^^^^
  File "/opt/anaconda3/envs/casher/lib/python3.11/site-packages/MySQLdb/__init__.py", line 130, in Connect
    return Connection(*args, **kwargs)
           ^^^^^^^^^^^^^^^^^^^^^^^^^^^
  File "/opt/anaconda3/envs/casher/lib/python3.11/site-packages/MySQLdb/connections.py", line 185, in __init__
    super().__init__(*args, **kwargs2)
MySQLdb._exceptions.OperationalError: (2059, "Authentication plugin 'caching_sha2_password' cannot be loaded: dlopen(/opt/anaconda3/envs/casher/lib/plugin/caching_sha2_password.so, 0x0002): tried: '/opt/anaconda3/envs/casher/lib/plugin/caching_sha2_password.so' (no such file)")

The above exception was the direct cause of the following exception:

Traceback (most recent call last):
  File "/opt/anaconda3/envs/casher/lib/python3.11/site-packages/asgiref/sync.py", line 518, in thread_handler
    raise exc_info[1]
  File "/opt/anaconda3/envs/casher/lib/python3.11/site-packages/django/core/handlers/exception.py", line 42, in inner
    response = await get_response(request)
               ^^^^^^^^^^^^^^^^^^^^^^^^^^^
  File "/opt/anaconda3/envs/casher/lib/python3.11/site-packages/asgiref/sync.py", line 518, in thread_handler
    raise exc_info[1]
  File "/opt/anaconda3/envs/casher/lib/python3.11/site-packages/django/core/handlers/base.py", line 253, in _get_response_async
    response = await wrapped_callback(
               ^^^^^^^^^^^^^^^^^^^^^^^
  File "/opt/anaconda3/envs/casher/lib/python3.11/site-packages/asgiref/sync.py", line 468, in __call__
    ret = await asyncio.shield(exec_coro)
          ^^^^^^^^^^^^^^^^^^^^^^^^^^^^^^^
  File "/opt/anaconda3/envs/casher/lib/python3.11/site-packages/asgiref/current_thread_executor.py", line 40, in run
    result = self.fn(*self.args, **self.kwargs)
             ^^^^^^^^^^^^^^^^^^^^^^^^^^^^^^^^^^
  File "/opt/anaconda3/envs/casher/lib/python3.11/site-packages/asgiref/sync.py", line 522, in thread_handler
    return func(*args, **kwargs)
           ^^^^^^^^^^^^^^^^^^^^^
  File "/opt/anaconda3/envs/casher/lib/python3.11/site-packages/django/views/decorators/csrf.py", line 56, in wrapper_view
    return view_func(*args, **kwargs)
           ^^^^^^^^^^^^^^^^^^^^^^^^^^
  File "/opt/anaconda3/envs/casher/lib/python3.11/site-packages/django/views/generic/base.py", line 104, in view
    return self.dispatch(request, *args, **kwargs)
           ^^^^^^^^^^^^^^^^^^^^^^^^^^^^^^^^^^^^^^^
  File "/opt/anaconda3/envs/casher/lib/python3.11/site-packages/rest_framework/views.py", line 509, in dispatch
    response = self.handle_exception(exc)
               ^^^^^^^^^^^^^^^^^^^^^^^^^^
  File "/opt/anaconda3/envs/casher/lib/python3.11/site-packages/rest_framework/views.py", line 469, in handle_exception
    self.raise_uncaught_exception(exc)
  File "/opt/anaconda3/envs/casher/lib/python3.11/site-packages/rest_framework/views.py", line 480, in raise_uncaught_exception
    raise exc
  File "/opt/anaconda3/envs/casher/lib/python3.11/site-packages/rest_framework/views.py", line 506, in dispatch
    response = handler(request, *args, **kwargs)
               ^^^^^^^^^^^^^^^^^^^^^^^^^^^^^^^^^
  File "/Users/amaozhao/workspace/casher/flow/views.py", line 535, in get
    banner = WorkFlowBanner.objects.first()
             ^^^^^^^^^^^^^^^^^^^^^^^^^^^^^^
  File "/opt/anaconda3/envs/casher/lib/python3.11/site-packages/django/db/models/manager.py", line 87, in manager_method
    return getattr(self.get_queryset(), name)(*args, **kwargs)
           ^^^^^^^^^^^^^^^^^^^^^^^^^^^^^^^^^^^^^^^^^^^^^^^^^^^
  File "/opt/anaconda3/envs/casher/lib/python3.11/site-packages/django/db/models/query.py", line 1057, in first
    for obj in queryset[:1]:
  File "/opt/anaconda3/envs/casher/lib/python3.11/site-packages/django/db/models/query.py", line 398, in __iter__
    self._fetch_all()
  File "/opt/anaconda3/envs/casher/lib/python3.11/site-packages/django/db/models/query.py", line 1881, in _fetch_all
    self._result_cache = list(self._iterable_class(self))
                         ^^^^^^^^^^^^^^^^^^^^^^^^^^^^^^^^
  File "/opt/anaconda3/envs/casher/lib/python3.11/site-packages/django/db/models/query.py", line 91, in __iter__
    results = compiler.execute_sql(
              ^^^^^^^^^^^^^^^^^^^^^
  File "/opt/anaconda3/envs/casher/lib/python3.11/site-packages/django/db/models/sql/compiler.py", line 1560, in execute_sql
    cursor = self.connection.cursor()
             ^^^^^^^^^^^^^^^^^^^^^^^^
  File "/opt/anaconda3/envs/casher/lib/python3.11/site-packages/django/utils/asyncio.py", line 26, in inner
    return func(*args, **kwargs)
           ^^^^^^^^^^^^^^^^^^^^^
  File "/opt/anaconda3/envs/casher/lib/python3.11/site-packages/django/db/backends/base/base.py", line 330, in cursor
    return self._cursor()
           ^^^^^^^^^^^^^^
  File "/opt/anaconda3/envs/casher/lib/python3.11/site-packages/django/db/backends/base/base.py", line 306, in _cursor
    self.ensure_connection()
  File "/opt/anaconda3/envs/casher/lib/python3.11/site-packages/django/utils/asyncio.py", line 26, in inner
    return func(*args, **kwargs)
           ^^^^^^^^^^^^^^^^^^^^^
  File "/opt/anaconda3/envs/casher/lib/python3.11/site-packages/django/db/backends/base/base.py", line 288, in ensure_connection
    with self.wrap_database_errors:
  File "/opt/anaconda3/envs/casher/lib/python3.11/site-packages/django/db/utils.py", line 91, in __exit__
    raise dj_exc_value.with_traceback(traceback) from exc_value
  File "/opt/anaconda3/envs/casher/lib/python3.11/site-packages/django/db/backends/base/base.py", line 289, in ensure_connection
    self.connect()
  File "/opt/anaconda3/envs/casher/lib/python3.11/site-packages/django/utils/asyncio.py", line 26, in inner
    return func(*args, **kwargs)
           ^^^^^^^^^^^^^^^^^^^^^
  File "/opt/anaconda3/envs/casher/lib/python3.11/site-packages/django/db/backends/base/base.py", line 270, in connect
    self.connection = self.get_new_connection(conn_params)
                      ^^^^^^^^^^^^^^^^^^^^^^^^^^^^^^^^^^^^
  File "/opt/anaconda3/envs/casher/lib/python3.11/site-packages/django/utils/asyncio.py", line 26, in inner
    return func(*args, **kwargs)
           ^^^^^^^^^^^^^^^^^^^^^
  File "/opt/anaconda3/envs/casher/lib/python3.11/site-packages/django/db/backends/mysql/base.py", line 247, in get_new_connection
    connection = Database.connect(**conn_params)
                 ^^^^^^^^^^^^^^^^^^^^^^^^^^^^^^^
  File "/opt/anaconda3/envs/casher/lib/python3.11/site-packages/MySQLdb/__init__.py", line 130, in Connect
    return Connection(*args, **kwargs)
           ^^^^^^^^^^^^^^^^^^^^^^^^^^^
  File "/opt/anaconda3/envs/casher/lib/python3.11/site-packages/MySQLdb/connections.py", line 185, in __init__
    super().__init__(*args, **kwargs2)
django.db.utils.OperationalError: (2059, "Authentication plugin 'caching_sha2_password' cannot be loaded: dlopen(/opt/anaconda3/envs/casher/lib/plugin/caching_sha2_password.so, 0x0002): tried: '/opt/anaconda3/envs/casher/lib/plugin/caching_sha2_password.so' (no such file)")
Response: 500
Request: GET /flow/banner/
Form data: <QueryDict: {}>
Internal Server Error: /flow/banner/
Traceback (most recent call last):
  File "/opt/anaconda3/envs/casher/lib/python3.11/site-packages/django/db/backends/base/base.py", line 289, in ensure_connection
    self.connect()
  File "/opt/anaconda3/envs/casher/lib/python3.11/site-packages/django/utils/asyncio.py", line 26, in inner
    return func(*args, **kwargs)
           ^^^^^^^^^^^^^^^^^^^^^
  File "/opt/anaconda3/envs/casher/lib/python3.11/site-packages/django/db/backends/base/base.py", line 270, in connect
    self.connection = self.get_new_connection(conn_params)
                      ^^^^^^^^^^^^^^^^^^^^^^^^^^^^^^^^^^^^
  File "/opt/anaconda3/envs/casher/lib/python3.11/site-packages/django/utils/asyncio.py", line 26, in inner
    return func(*args, **kwargs)
           ^^^^^^^^^^^^^^^^^^^^^
  File "/opt/anaconda3/envs/casher/lib/python3.11/site-packages/django/db/backends/mysql/base.py", line 247, in get_new_connection
    connection = Database.connect(**conn_params)
                 ^^^^^^^^^^^^^^^^^^^^^^^^^^^^^^^
  File "/opt/anaconda3/envs/casher/lib/python3.11/site-packages/MySQLdb/__init__.py", line 130, in Connect
    return Connection(*args, **kwargs)
           ^^^^^^^^^^^^^^^^^^^^^^^^^^^
  File "/opt/anaconda3/envs/casher/lib/python3.11/site-packages/MySQLdb/connections.py", line 185, in __init__
    super().__init__(*args, **kwargs2)
MySQLdb._exceptions.OperationalError: (2059, "Authentication plugin 'caching_sha2_password' cannot be loaded: dlopen(/opt/anaconda3/envs/casher/lib/plugin/caching_sha2_password.so, 0x0002): tried: '/opt/anaconda3/envs/casher/lib/plugin/caching_sha2_password.so' (no such file)")

The above exception was the direct cause of the following exception:

Traceback (most recent call last):
  File "/opt/anaconda3/envs/casher/lib/python3.11/site-packages/asgiref/sync.py", line 518, in thread_handler
    raise exc_info[1]
  File "/opt/anaconda3/envs/casher/lib/python3.11/site-packages/django/core/handlers/exception.py", line 42, in inner
    response = await get_response(request)
               ^^^^^^^^^^^^^^^^^^^^^^^^^^^
  File "/opt/anaconda3/envs/casher/lib/python3.11/site-packages/asgiref/sync.py", line 518, in thread_handler
    raise exc_info[1]
  File "/opt/anaconda3/envs/casher/lib/python3.11/site-packages/django/core/handlers/base.py", line 253, in _get_response_async
    response = await wrapped_callback(
               ^^^^^^^^^^^^^^^^^^^^^^^
  File "/opt/anaconda3/envs/casher/lib/python3.11/site-packages/asgiref/sync.py", line 468, in __call__
    ret = await asyncio.shield(exec_coro)
          ^^^^^^^^^^^^^^^^^^^^^^^^^^^^^^^
  File "/opt/anaconda3/envs/casher/lib/python3.11/site-packages/asgiref/current_thread_executor.py", line 40, in run
    result = self.fn(*self.args, **self.kwargs)
             ^^^^^^^^^^^^^^^^^^^^^^^^^^^^^^^^^^
  File "/opt/anaconda3/envs/casher/lib/python3.11/site-packages/asgiref/sync.py", line 522, in thread_handler
    return func(*args, **kwargs)
           ^^^^^^^^^^^^^^^^^^^^^
  File "/opt/anaconda3/envs/casher/lib/python3.11/site-packages/django/views/decorators/csrf.py", line 56, in wrapper_view
    return view_func(*args, **kwargs)
           ^^^^^^^^^^^^^^^^^^^^^^^^^^
  File "/opt/anaconda3/envs/casher/lib/python3.11/site-packages/django/views/generic/base.py", line 104, in view
    return self.dispatch(request, *args, **kwargs)
           ^^^^^^^^^^^^^^^^^^^^^^^^^^^^^^^^^^^^^^^
  File "/opt/anaconda3/envs/casher/lib/python3.11/site-packages/rest_framework/views.py", line 509, in dispatch
    response = self.handle_exception(exc)
               ^^^^^^^^^^^^^^^^^^^^^^^^^^
  File "/opt/anaconda3/envs/casher/lib/python3.11/site-packages/rest_framework/views.py", line 469, in handle_exception
    self.raise_uncaught_exception(exc)
  File "/opt/anaconda3/envs/casher/lib/python3.11/site-packages/rest_framework/views.py", line 480, in raise_uncaught_exception
    raise exc
  File "/opt/anaconda3/envs/casher/lib/python3.11/site-packages/rest_framework/views.py", line 506, in dispatch
    response = handler(request, *args, **kwargs)
               ^^^^^^^^^^^^^^^^^^^^^^^^^^^^^^^^^
  File "/Users/amaozhao/workspace/casher/flow/views.py", line 535, in get
    banner = WorkFlowBanner.objects.first()
             ^^^^^^^^^^^^^^^^^^^^^^^^^^^^^^
  File "/opt/anaconda3/envs/casher/lib/python3.11/site-packages/django/db/models/manager.py", line 87, in manager_method
    return getattr(self.get_queryset(), name)(*args, **kwargs)
           ^^^^^^^^^^^^^^^^^^^^^^^^^^^^^^^^^^^^^^^^^^^^^^^^^^^
  File "/opt/anaconda3/envs/casher/lib/python3.11/site-packages/django/db/models/query.py", line 1057, in first
    for obj in queryset[:1]:
  File "/opt/anaconda3/envs/casher/lib/python3.11/site-packages/django/db/models/query.py", line 398, in __iter__
    self._fetch_all()
  File "/opt/anaconda3/envs/casher/lib/python3.11/site-packages/django/db/models/query.py", line 1881, in _fetch_all
    self._result_cache = list(self._iterable_class(self))
                         ^^^^^^^^^^^^^^^^^^^^^^^^^^^^^^^^
  File "/opt/anaconda3/envs/casher/lib/python3.11/site-packages/django/db/models/query.py", line 91, in __iter__
    results = compiler.execute_sql(
              ^^^^^^^^^^^^^^^^^^^^^
  File "/opt/anaconda3/envs/casher/lib/python3.11/site-packages/django/db/models/sql/compiler.py", line 1560, in execute_sql
    cursor = self.connection.cursor()
             ^^^^^^^^^^^^^^^^^^^^^^^^
  File "/opt/anaconda3/envs/casher/lib/python3.11/site-packages/django/utils/asyncio.py", line 26, in inner
    return func(*args, **kwargs)
           ^^^^^^^^^^^^^^^^^^^^^
  File "/opt/anaconda3/envs/casher/lib/python3.11/site-packages/django/db/backends/base/base.py", line 330, in cursor
    return self._cursor()
           ^^^^^^^^^^^^^^
  File "/opt/anaconda3/envs/casher/lib/python3.11/site-packages/django/db/backends/base/base.py", line 306, in _cursor
    self.ensure_connection()
  File "/opt/anaconda3/envs/casher/lib/python3.11/site-packages/django/utils/asyncio.py", line 26, in inner
    return func(*args, **kwargs)
           ^^^^^^^^^^^^^^^^^^^^^
  File "/opt/anaconda3/envs/casher/lib/python3.11/site-packages/django/db/backends/base/base.py", line 288, in ensure_connection
    with self.wrap_database_errors:
  File "/opt/anaconda3/envs/casher/lib/python3.11/site-packages/django/db/utils.py", line 91, in __exit__
    raise dj_exc_value.with_traceback(traceback) from exc_value
  File "/opt/anaconda3/envs/casher/lib/python3.11/site-packages/django/db/backends/base/base.py", line 289, in ensure_connection
    self.connect()
  File "/opt/anaconda3/envs/casher/lib/python3.11/site-packages/django/utils/asyncio.py", line 26, in inner
    return func(*args, **kwargs)
           ^^^^^^^^^^^^^^^^^^^^^
  File "/opt/anaconda3/envs/casher/lib/python3.11/site-packages/django/db/backends/base/base.py", line 270, in connect
    self.connection = self.get_new_connection(conn_params)
                      ^^^^^^^^^^^^^^^^^^^^^^^^^^^^^^^^^^^^
  File "/opt/anaconda3/envs/casher/lib/python3.11/site-packages/django/utils/asyncio.py", line 26, in inner
    return func(*args, **kwargs)
           ^^^^^^^^^^^^^^^^^^^^^
  File "/opt/anaconda3/envs/casher/lib/python3.11/site-packages/django/db/backends/mysql/base.py", line 247, in get_new_connection
    connection = Database.connect(**conn_params)
                 ^^^^^^^^^^^^^^^^^^^^^^^^^^^^^^^
  File "/opt/anaconda3/envs/casher/lib/python3.11/site-packages/MySQLdb/__init__.py", line 130, in Connect
    return Connection(*args, **kwargs)
           ^^^^^^^^^^^^^^^^^^^^^^^^^^^
  File "/opt/anaconda3/envs/casher/lib/python3.11/site-packages/MySQLdb/connections.py", line 185, in __init__
    super().__init__(*args, **kwargs2)
django.db.utils.OperationalError: (2059, "Authentication plugin 'caching_sha2_password' cannot be loaded: dlopen(/opt/anaconda3/envs/casher/lib/plugin/caching_sha2_password.so, 0x0002): tried: '/opt/anaconda3/envs/casher/lib/plugin/caching_sha2_password.so' (no such file)")
Response: 500
Request: GET /flow/banner/
Form data: <QueryDict: {}>
Response: 200
Response content: 



<!DOCTYPE html>
<html>
  <head>
    

      
        <meta http-equiv="Content-Type" content="text/html; charset=utf-8"/>
        <meta name="robots" content="NONE,NOARCHIVE" />
      

      <title>Work Flow Banner – Django REST framework</title>

      
        
          <link rel="stylesheet" type="text/css" href="/static/rest_framework/css/bootstrap.min.css"/>
          <link rel="stylesheet" type="text/css" href="/static/rest_framework/css/bootstrap-tweaks.css"/>
        

        <link rel="stylesheet" type="text/css" href="/static/rest_framework/css/prettify.css"/>
        <link rel="stylesheet" type="text/css" href="/static/rest_framework/css/default.css"/>
        
      

    
  </head>

  
  <body class="">

    <div class="wrapper">
      
        <div class="navbar navbar-static-top navbar-inverse"
             role="navigation" aria-label="navbar">
          <div class="container">
            <span>
              
                <a class='navbar-brand' rel="nofollo
Request: GET /static/rest_framework/css/bootstrap.min.css
Form data: <QueryDict: {}>
Request: GET /static/rest_framework/js/jquery-3.7.1.min.js
Request: GET /static/rest_framework/js/prettify-min.js
Request: GET /static/rest_framework/css/default.css
Form data: <QueryDict: {}>
Request: GET /static/rest_framework/css/prettify.css
Form data: <QueryDict: {}>
Form data: <QueryDict: {}>
Form data: <QueryDict: {}>
Request: GET /static/rest_framework/js/bootstrap.min.js
Form data: <QueryDict: {}>
Response: 200
Response: 304
Response: 304
Response: 200
Response: 200
Response: 200
Request: GET /static/rest_framework/css/bootstrap-tweaks.css
Form data: <QueryDict: {}>
Request: GET /static/rest_framework/js/csrf.js
Form data: <QueryDict: {}>
Response: 304
Response: 304
Request: GET /static/rest_framework/js/default.js
Form data: <QueryDict: {}>
Request: GET /static/rest_framework/js/load-ajax-form.js
Form data: <QueryDict: {}>
Response: 304
Response: 304
Request: GET /static/rest_framework/js/ajax-form.js
Form data: <QueryDict: {}>
Internal Server Error: /static/rest_framework/js/prettify-min.js
Traceback (most recent call last):
  File "/opt/anaconda3/envs/casher/lib/python3.11/site-packages/django/core/handlers/exception.py", line 55, in inner
    response = get_response(request)
               ^^^^^^^^^^^^^^^^^^^^^
  File "/Users/amaozhao/workspace/casher/casher/log_middleware.py", line 27, in __call__
    logger.info(f"Response content: {response.content.decode('utf-8')[:1000]}")  # 限制日志内容的长度
                                     ^^^^^^^^^^^^^^^^
  File "/opt/anaconda3/envs/casher/lib/python3.11/site-packages/django/http/response.py", line 458, in content
    raise AttributeError(
AttributeError: This FileResponse instance has no `content` attribute. Use `streaming_content` instead.
Internal Server Error: /static/rest_framework/css/bootstrap.min.css
Traceback (most recent call last):
  File "/opt/anaconda3/envs/casher/lib/python3.11/site-packages/django/core/handlers/exception.py", line 55, in inner
    response = get_response(request)
               ^^^^^^^^^^^^^^^^^^^^^
  File "/Users/amaozhao/workspace/casher/casher/log_middleware.py", line 27, in __call__
    logger.info(f"Response content: {response.content.decode('utf-8')[:1000]}")  # 限制日志内容的长度
                                     ^^^^^^^^^^^^^^^^
  File "/opt/anaconda3/envs/casher/lib/python3.11/site-packages/django/http/response.py", line 458, in content
    raise AttributeError(
AttributeError: This FileResponse instance has no `content` attribute. Use `streaming_content` instead.
Internal Server Error: /static/rest_framework/js/jquery-3.7.1.min.js
Traceback (most recent call last):
  File "/opt/anaconda3/envs/casher/lib/python3.11/site-packages/django/core/handlers/exception.py", line 55, in inner
    response = get_response(request)
               ^^^^^^^^^^^^^^^^^^^^^
  File "/Users/amaozhao/workspace/casher/casher/log_middleware.py", line 27, in __call__
    logger.info(f"Response content: {response.content.decode('utf-8')[:1000]}")  # 限制日志内容的长度
                                     ^^^^^^^^^^^^^^^^
  File "/opt/anaconda3/envs/casher/lib/python3.11/site-packages/django/http/response.py", line 458, in content
    raise AttributeError(
AttributeError: This FileResponse instance has no `content` attribute. Use `streaming_content` instead.
Internal Server Error: /static/rest_framework/js/bootstrap.min.js
Traceback (most recent call last):
  File "/opt/anaconda3/envs/casher/lib/python3.11/site-packages/django/core/handlers/exception.py", line 55, in inner
    response = get_response(request)
               ^^^^^^^^^^^^^^^^^^^^^
  File "/Users/amaozhao/workspace/casher/casher/log_middleware.py", line 27, in __call__
    logger.info(f"Response content: {response.content.decode('utf-8')[:1000]}")  # 限制日志内容的长度
                                     ^^^^^^^^^^^^^^^^
  File "/opt/anaconda3/envs/casher/lib/python3.11/site-packages/django/http/response.py", line 458, in content
    raise AttributeError(
AttributeError: This FileResponse instance has no `content` attribute. Use `streaming_content` instead.
Response: 304
Request: GET /static/rest_framework/img/grid.png
Form data: <QueryDict: {}>
Response: 304
Request: GET /flow/banner/
Form data: <QueryDict: {}>
Response: 200
Response content: 



<!DOCTYPE html>
<html>
  <head>
    

      
        <meta http-equiv="Content-Type" content="text/html; charset=utf-8"/>
        <meta name="robots" content="NONE,NOARCHIVE" />
      

      <title>Work Flow Banner – Django REST framework</title>

      
        
          <link rel="stylesheet" type="text/css" href="/static/rest_framework/css/bootstrap.min.css"/>
          <link rel="stylesheet" type="text/css" href="/static/rest_framework/css/bootstrap-tweaks.css"/>
        

        <link rel="stylesheet" type="text/css" href="/static/rest_framework/css/prettify.css"/>
        <link rel="stylesheet" type="text/css" href="/static/rest_framework/css/default.css"/>
        
      

    
  </head>

  
  <body class="">

    <div class="wrapper">
      
        <div class="navbar navbar-static-top navbar-inverse"
             role="navigation" aria-label="navbar">
          <div class="container">
            <span>
              
                <a class='navbar-brand' rel="nofollo
Request: GET /static/rest_framework/css/bootstrap.min.css
Form data: <QueryDict: {}>
Request: GET /static/rest_framework/js/jquery-3.7.1.min.js
Form data: <QueryDict: {}>
Response: 200
Response: 200
Internal Server Error: /static/rest_framework/js/jquery-3.7.1.min.js
Traceback (most recent call last):
  File "/opt/anaconda3/envs/casher/lib/python3.11/site-packages/django/core/handlers/exception.py", line 55, in inner
    response = get_response(request)
               ^^^^^^^^^^^^^^^^^^^^^
  File "/Users/amaozhao/workspace/casher/casher/log_middleware.py", line 27, in __call__
    logger.info(f"Response content: {response.content.decode('utf-8')[:1000]}")  # 限制日志内容的长度
                                     ^^^^^^^^^^^^^^^^
  File "/opt/anaconda3/envs/casher/lib/python3.11/site-packages/django/http/response.py", line 458, in content
    raise AttributeError(
AttributeError: This FileResponse instance has no `content` attribute. Use `streaming_content` instead.
Request: GET /static/rest_framework/js/prettify-min.js
Form data: <QueryDict: {}>
Request: GET /static/rest_framework/js/bootstrap.min.js
Form data: <QueryDict: {}>
Internal Server Error: /static/rest_framework/css/bootstrap.min.css
Traceback (most recent call last):
  File "/opt/anaconda3/envs/casher/lib/python3.11/site-packages/django/core/handlers/exception.py", line 55, in inner
    response = get_response(request)
               ^^^^^^^^^^^^^^^^^^^^^
  File "/Users/amaozhao/workspace/casher/casher/log_middleware.py", line 27, in __call__
    logger.info(f"Response content: {response.content.decode('utf-8')[:1000]}")  # 限制日志内容的长度
                                     ^^^^^^^^^^^^^^^^
  File "/opt/anaconda3/envs/casher/lib/python3.11/site-packages/django/http/response.py", line 458, in content
    raise AttributeError(
AttributeError: This FileResponse instance has no `content` attribute. Use `streaming_content` instead.
Response: 200
Response: 200
Internal Server Error: /static/rest_framework/js/prettify-min.js
Traceback (most recent call last):
  File "/opt/anaconda3/envs/casher/lib/python3.11/site-packages/django/core/handlers/exception.py", line 55, in inner
    response = get_response(request)
               ^^^^^^^^^^^^^^^^^^^^^
  File "/Users/amaozhao/workspace/casher/casher/log_middleware.py", line 27, in __call__
    logger.info(f"Response content: {response.content.decode('utf-8')[:1000]}")  # 限制日志内容的长度
                                     ^^^^^^^^^^^^^^^^
  File "/opt/anaconda3/envs/casher/lib/python3.11/site-packages/django/http/response.py", line 458, in content
    raise AttributeError(
AttributeError: This FileResponse instance has no `content` attribute. Use `streaming_content` instead.
Internal Server Error: /static/rest_framework/js/bootstrap.min.js
Traceback (most recent call last):
  File "/opt/anaconda3/envs/casher/lib/python3.11/site-packages/django/core/handlers/exception.py", line 55, in inner
    response = get_response(request)
               ^^^^^^^^^^^^^^^^^^^^^
  File "/Users/amaozhao/workspace/casher/casher/log_middleware.py", line 27, in __call__
    logger.info(f"Response content: {response.content.decode('utf-8')[:1000]}")  # 限制日志内容的长度
                                     ^^^^^^^^^^^^^^^^
  File "/opt/anaconda3/envs/casher/lib/python3.11/site-packages/django/http/response.py", line 458, in content
    raise AttributeError(
AttributeError: This FileResponse instance has no `content` attribute. Use `streaming_content` instead.
Request: POST /task/prompt/
JSON data: {
    "workflow_id": "7",
    "image_url": "https://aidep.cn/media/cs/images/1_GL1RElk.jpg",
    "prompt_text": "1111"
}
Response: 401
